<?xml version="1.0"?>
<robot name="diff_drive_robot">

  <link name="base_link">
    <visual>
      <geometry>
        <box size="0.4 0.2 0.1"/>
      </geometry>
      <origin xyz="0 0 0.05" rpy="0 0 0"/>
      <material name="blue">
        <color rgba="0.0 0.0 0.8 1.0"/>
      </material>
    </visual>
  </link>

  <link name="left_wheel_link">
    <visual>
      <geometry>
        <cylinder radius="0.05" length="0.04"/>
      </geometry>
      <origin xyz="0 0 0" rpy="1.5707 0 0"/>
      <material name="black">
        <color rgba="0.0 0.0 0.0 1.0"/>
      </material>
    </visual>
  </link>

  <link name="right_wheel_link">
    <visual>
      <geometry>
        <cylinder radius="0.05" length="0.04"/>
      </geometry>
      <origin xyz="0 0 0" rpy="1.5707 0 0"/>
      <material name="black"/>
    </visual>
  </link>

  <joint name="left_wheel_joint" type="continuous">
    <parent link="base_link"/>
    <child link="left_wheel_link"/>
    <origin xyz="0.1 0.13 0" rpy="0 0 0"/>
    <axis xyz="0 1 0"/>
  </joint>

  <joint name="right_wheel_joint" type="continuous">
    <parent link="base_link"/>
    <child link="right_wheel_link"/>
    <origin xyz="0.1 -0.13 0" rpy="0 0 0"/>
    <axis xyz="0 1 0"/>
  </joint>

</robot>